<?xml version="1.0" ?>
<!-- =================================================================================== -->
<!-- |    This document was autogenerated by xacro from /home/nesc/balance_car_ws/src/balance_description/urdf/balance.urdf.xacro | -->
<!-- |    EDITING THIS FILE BY HAND IS NOT RECOMMENDED                                 | -->
<!-- =================================================================================== -->
<robot name="balance_bot">
  <!-- =================================================================================== -->
  <!-- Macros -->
  <!-- =================================================================================== -->
  <!-- Materials -->
  <material name="orange">
    <color rgba="1.0 0.4235294117647059 0.0392156862745098 1.0"/>
  </material>
  <material name="black">
    <color rgba="0.0 0.0 0.0 1.0"/>
  </material>
  <material name="blue">
    <color rgba="0 0 0.8 1"/>
  </material>
  <material name="white">
    <color rgba="1 1 1 1"/>
  </material>
  <!-- =================================================================================== -->
  <!-- Base & Body -->
  <!-- =================================================================================== -->
  <link name="base_footprint"/>
  <joint name="base_joint" type="fixed">
    <parent link="base_footprint"/>
    <child link="base_link"/>
    <origin rpy="0.0 0.0 0.0" xyz="0.0 0.0 0.1305"/>
  </joint>
  <link name="base_link">
    <visual>
      <geometry>
        <box size="0.5 0.5 0.061"/>
      </geometry>
      <material name="blue"/>
    </visual>
    <collision>
      <geometry>
        <box size="0.5 0.5 0.061"/>
      </geometry>
    </collision>
    <inertial>
      <origin rpy="0.0 0.0 0.0" xyz="-0.015 0.0 0.0"/>
      <mass value="2.0"/>
      <inertia ixx="0.04229" ixy="0.0" ixz="0.0" iyy="0.04229" iyz="0.0" izz="0.08333"/>
    </inertial>
  </link>
  <!-- Sensors: IMU -->
  <link name="imu_link">
    <visual>
      <geometry>
        <box size="0.01 0.01 0.01"/>
      </geometry>
    </visual>
    <inertial>
      <mass value="0.001"/>
      <inertia ixx="1.6666666666666667e-08" ixy="0.0" ixz="0.0" iyy="1.6666666666666667e-08" iyz="0.0" izz="1.6666666666666667e-08"/>
    </inertial>
  </link>
  <joint name="imu_joint" type="fixed">
    <parent link="base_link"/>
    <child link="imu_link"/>
  </joint>
  <!-- =================================================================================== -->
  <!-- Gimbal System -->
  <!-- =================================================================================== -->
  <link name="gimbal_link">
    <visual>
      <geometry>
        <cylinder length="0.12" radius="0.06"/>
      </geometry>
      <material name="white"/>
    </visual>
    <collision>
      <geometry>
        <cylinder length="0.12" radius="0.06"/>
      </geometry>
    </collision>
    <inertial>
      <mass value="0.2"/>
      <inertia ixx="0.00042" ixy="0.0" ixz="0.0" iyy="0.00042" iyz="0.0" izz="0.00035999999999999997"/>
    </inertial>
  </link>
  <joint name="gimbal_joint" type="continuous">
    <parent link="base_link"/>
    <child link="gimbal_link"/>
    <origin rpy="0 0 0" xyz="0 0 0.0905"/>
    <axis xyz="0 0 1"/>
    <limit effort="3.07" lower="-1.0" upper="1.0" velocity="70"/>
  </joint>
  <transmission name="gimbal_trans">
    <type>transmission_interface/SimpleTransmission</type>
    <joint name="gimbal_joint">
      <hardwareInterface>hardware_interface/EffortJointInterface</hardwareInterface>
    </joint>
    <actuator name="gimbal_motor">
      <mechanicalReduction>1</mechanicalReduction>
    </actuator>
  </transmission>
  <link name="muzzle_link">
    <visual>
      <origin rpy="0 1.5707963267948966 0" xyz="0.04 0.0 0.0"/>
      <geometry>
        <cylinder length="0.4" radius="0.03"/>
      </geometry>
      <material name="white"/>
    </visual>
    <collision>
      <origin rpy="0 1.5707963267948966 0" xyz="0.2 0.0 0.0"/>
      <geometry>
        <cylinder length="0.4" radius="0.03"/>
      </geometry>
    </collision>
    <inertial>
      <mass value="0.8"/>
      <origin xyz="0 0 0"/>
      <inertia ixx="0.00036" ixy="0.0" ixz="0.0" iyy="0.01085" iyz="0.0" izz="0.0079"/>
    </inertial>
  </link>
  <joint name="muzzle_joint" type="revolute">
    <parent link="gimbal_link"/>
    <child link="muzzle_link"/>
    <origin rpy="0 0 0" xyz="0.0 0 0.15"/>
    <axis xyz="0 1 0"/>
    <limit effort="3" lower="-0.5" upper="0.24" velocity="70"/>
  </joint>
  <link name="gimbal_imu_link">
    <visual>
      <geometry>
        <box size="0.01 0.01 0.01"/>
      </geometry>
    </visual>
    <inertial>
      <mass value="0.001"/>
      <inertia ixx="1.6666666666666667e-08" ixy="0.0" ixz="0.0" iyy="1.6666666666666667e-08" iyz="0.0" izz="1.6666666666666667e-08"/>
    </inertial>
  </link>
  <joint name="gimbal_imu_joint" type="fixed">
    <parent link="muzzle_link"/>
    <child link="gimbal_imu_link"/>
  </joint>
  <transmission name="muzzle_trans">
    <type>transmission_interface/SimpleTransmission</type>
    <joint name="muzzle_joint">
      <hardwareInterface>hardware_interface/EffortJointInterface</hardwareInterface>
    </joint>
    <actuator name="muzzle_motor">
      <mechanicalReduction>1</mechanicalReduction>
    </actuator>
  </transmission>
  <!-- =================================================================================== -->
  <!-- Leg Macro (Optimized with closed chain structure and Wheels) -->
  <!-- =================================================================================== -->
  <!-- 1. Thigh (First Leg) -->
  <link name="left_thigh_link">
    <visual>
      <origin rpy="0.0 0.0 0.0" xyz="0.0 0.0 -0.14"/>
      <geometry>
        <box size="0.05 0.01 0.4"/>
      </geometry>
      <material name="black"/>
    </visual>
    <collision>
      <origin rpy="0.0 0.0 0.0" xyz="0.0 0.0 -0.14"/>
      <geometry>
        <box size="0.05 0.01 0.4"/>
      </geometry>
    </collision>
    <inertial>
      <mass value="0.1"/>
      <inertia ixx="0.0013341666666666669" ixy="0.0" ixz="0.0" iyy="2.166666666666667e-05" iyz="0.0" izz="0.001354166666666667"/>
    </inertial>
  </link>
  <joint name="left_hip_joint" type="continuous">
    <origin rpy="0.0 1.0471975511965976 0.0" xyz="0.0 0.255 0"/>
    <parent link="base_link"/>
    <child link="left_thigh_link"/>
    <axis xyz="0.0 1 0.0"/>
  </joint>
  <!-- 2. Shank (Second Leg) -->
  <link name="left_shank_link">
    <visual>
      <origin rpy="0.0 0.0 0.0" xyz="0.0 0.0 -0.15"/>
      <geometry>
        <box size="0.05 0.01 0.5"/>
      </geometry>
      <material name="black"/>
    </visual>
    <collision>
      <origin rpy="0.0 0.0 0.0" xyz="0.0 0.0 -0.15"/>
      <geometry>
        <box size="0.05 0.01 0.5"/>
      </geometry>
    </collision>
    <inertial>
      <mass value="0.1"/>
      <inertia ixx="0.0020841666666666665" ixy="0.0" ixz="0.0" iyy="2.166666666666667e-05" iyz="0.0" izz="0.0021041666666666665"/>
    </inertial>
  </link>
  <joint name="left_knee_joint" type="revolute">
    <origin rpy="0.0 -1.56 0.0" xyz="0.0 0.0 -0.3"/>
    <parent link="left_thigh_link"/>
    <child link="left_shank_link"/>
    <axis xyz="0.0 1 0.0"/>
    <limit effort="3" lower="-0.72" upper="0.72" velocity="70"/>
  </joint>
  <!-- 3. Closed Chain Structure Elements (Auxiliary Linkages) -->
  <!-- Complex 1: Connects to Thigh -->
  <link name="left_linkage_1">
    <visual>
      <origin rpy="0.0 0.0 0.0" xyz="0.0 0.0 0"/>
      <geometry>
        <box size="0.04 0.01 0.17"/>
      </geometry>
      <material name="orange"/>
    </visual>
    <inertial>
      <mass value="0.05"/>
      <inertia ixx="0.00012083333333333335" ixy="0.0" ixz="0.0" iyy="7.083333333333334e-06" iyz="0.0" izz="0.00012708333333333335"/>
    </inertial>
  </link>
  <joint name="left_linkage_1_joint" type="revolute">
    <origin rpy="0.0 1.5707963267948966 0.0" xyz="0.0 0.0 -0.15"/>
    <parent link="left_thigh_link"/>
    <child link="left_linkage_1"/>
    <axis xyz="0.0 1 0.0"/>
    <limit effort="3" lower="-0.72" upper="0.72" velocity="70"/>
  </joint>
  <!-- Complex 2: Connects to Thigh -->
  <link name="left_linkage_2">
    <visual>
      <origin rpy="0.0 0.0 0.0" xyz="0.0 0.0 0.0425"/>
      <geometry>
        <box size="0.04 0.01 0.085"/>
      </geometry>
      <material name="orange"/>
    </visual>
    <inertial>
      <mass value="0.05"/>
      <inertia ixx="3.052083333333334e-05" ixy="0.0" ixz="0.0" iyy="7.083333333333334e-06" iyz="0.0" izz="3.677083333333334e-05"/>
    </inertial>
  </link>
  <joint name="left_linkage_2_joint" type="revolute">
    <origin rpy="0 2.6179938779914944 0" xyz="0 0.255 0"/>
    <parent link="base_link"/>
    <child link="left_linkage_2"/>
    <axis xyz="0.0 1 0.0"/>
    <limit effort="3" lower="-0.72" upper="0.72" velocity="70"/>
  </joint>
  <!-- Cross Connection 1: Connects to Linkage 2 -->
  <!-- Originally 'first_connect_complex' parent 'second_complex' (linkage_2) -->
  <link name="left_cross_conn_1">
    <visual>
      <origin rpy="0.0 0.0 0.0" xyz="0 0.0 0.07"/>
      <geometry>
        <box size="0.02 0.01 0.17"/>
      </geometry>
      <material name="white"/>
    </visual>
    <inertial>
      <mass value="0.02"/>
      <inertia ixx="4.833333333333335e-05" ixy="0.0" ixz="0.0" iyy="8.333333333333334e-07" iyz="0.0" izz="4.8833333333333346e-05"/>
    </inertial>
  </link>
  <joint name="left_cross_conn_1_joint" type="continuous">
    <origin rpy="0.0 1.5707963267948966 0.0" xyz="0 0 0.07"/>
    <parent link="left_linkage_2"/>
    <child link="left_cross_conn_1"/>
    <axis xyz="0.0 1 0.0"/>
  </joint>
  <!-- Cross Connection 2: Connects to Linkage 1 -->
  <!-- Originally 'second_connect_complex' parent 'first_complex' (linkage_1) -->
  <link name="left_cross_conn_2">
    <visual>
      <origin rpy="0.0 0.0 0.0" xyz="0 0.0 0.07"/>
      <geometry>
        <box size="0.02 0.01 0.17"/>
      </geometry>
      <material name="white"/>
    </visual>
    <inertial>
      <mass value="0.02"/>
      <inertia ixx="4.833333333333335e-05" ixy="0.0" ixz="0.0" iyy="8.333333333333334e-07" iyz="0.0" izz="4.8833333333333346e-05"/>
    </inertial>
  </link>
  <joint name="left_cross_conn_2_joint" type="continuous">
    <origin rpy="0.0 1.5707963267948966 0.0" xyz="0 0 -0.07"/>
    <parent link="left_linkage_1"/>
    <child link="left_cross_conn_2"/>
    <axis xyz="0.0 1 0.0"/>
  </joint>
  <!-- 4. Wheel -->
  <link name="left_wheel_link">
    <visual>
      <origin rpy="1.5707963267948966 0 0" xyz="0 0 0"/>
      <geometry>
        <cylinder length="0.03" radius="0.1"/>
      </geometry>
      <material name="black"/>
    </visual>
    <collision>
      <origin rpy="1.5707963267948966 0 0" xyz="0 0 0"/>
      <geometry>
        <cylinder length="0.03" radius="0.1"/>
      </geometry>
    </collision>
    <inertial>
      <mass value="0.5"/>
      <inertia ixx="0.0012875000000000002" ixy="0.0" ixz="0.0" iyy="0.0012875000000000002" iyz="0.0" izz="0.0025000000000000005"/>
    </inertial>
  </link>
  <joint name="left_wheel_joint" type="continuous">
    <origin rpy="0 0 0" xyz="0 0 -0.5"/>
    <parent link="left_shank_link"/>
    <child link="left_wheel_link"/>
    <axis xyz="0 1 0"/>
    <limit effort="100" velocity="100"/>
  </joint>
  <gazebo reference="left_wheel_link">
    <mu1>1.0</mu1>
    <mu2>1.0</mu2>
    <kp>1000000.0</kp>
    <kd>100.0</kd>
    <material>Gazebo/Black</material>
  </gazebo>
  <!-- Wheel Transmission -->
  <transmission name="left_wheel_trans">
    <type>transmission_interface/SimpleTransmission</type>
    <joint name="left_wheel_joint">
      <hardwareInterface>hardware_interface/EffortJointInterface</hardwareInterface>
    </joint>
    <actuator name="left_wheel_motor">
      <hardwareInterface>hardware_interface/EffortJointInterface</hardwareInterface>
      <mechanicalReduction>1</mechanicalReduction>
    </actuator>
  </transmission>
  <gazebo>
    <joint name="left_cross_conn_1_loop_joint" type="revolute">
      <parent>left_cross_conn_1</parent>
      <child>left_linkage_1</child>
      <axis>
        <xyz>0 1 0</xyz>
        <limit effort="10" lower="-3.14" upper="3.14" velocity="100"/>
      </axis>
      <pose>0 0 -0.07 0 0 0</pose>
    </joint>
  </gazebo>
  <gazebo>
    <joint name="left_cross_conn_2_loop_joint" type="revolute">
      <parent>left_cross_conn_2</parent>
      <child>left_shank_link</child>
      <axis>
        <xyz>0 1 0</xyz>
        <limit effort="10" lower="-3.14" upper="3.14" velocity="100"/>
      </axis>
      <pose>0 0 -0.07 0 0 0</pose>
    </joint>
  </gazebo>
  <!-- 1. Thigh (First Leg) -->
  <link name="right_thigh_link">
    <visual>
      <origin rpy="0.0 0.0 0.0" xyz="0.0 0.0 -0.14"/>
      <geometry>
        <box size="0.05 0.01 0.4"/>
      </geometry>
      <material name="black"/>
    </visual>
    <collision>
      <origin rpy="0.0 0.0 0.0" xyz="0.0 0.0 -0.14"/>
      <geometry>
        <box size="0.05 0.01 0.4"/>
      </geometry>
    </collision>
    <inertial>
      <mass value="0.1"/>
      <inertia ixx="0.0013341666666666669" ixy="0.0" ixz="0.0" iyy="2.166666666666667e-05" iyz="0.0" izz="0.001354166666666667"/>
    </inertial>
  </link>
  <joint name="right_hip_joint" type="continuous">
    <origin rpy="0.0 1.0471975511965976 0.0" xyz="0.0 -0.255 0"/>
    <parent link="base_link"/>
    <child link="right_thigh_link"/>
    <axis xyz="0.0 1 0.0"/>
  </joint>
  <!-- 2. Shank (Second Leg) -->
  <link name="right_shank_link">
    <visual>
      <origin rpy="0.0 0.0 0.0" xyz="0.0 0.0 -0.15"/>
      <geometry>
        <box size="0.05 0.01 0.5"/>
      </geometry>
      <material name="black"/>
    </visual>
    <collision>
      <origin rpy="0.0 0.0 0.0" xyz="0.0 0.0 -0.15"/>
      <geometry>
        <box size="0.05 0.01 0.5"/>
      </geometry>
    </collision>
    <inertial>
      <mass value="0.1"/>
      <inertia ixx="0.0020841666666666665" ixy="0.0" ixz="0.0" iyy="2.166666666666667e-05" iyz="0.0" izz="0.0021041666666666665"/>
    </inertial>
  </link>
  <joint name="right_knee_joint" type="revolute">
    <origin rpy="0.0 -1.56 0.0" xyz="0.0 0.0 -0.3"/>
    <parent link="right_thigh_link"/>
    <child link="right_shank_link"/>
    <axis xyz="0.0 1 0.0"/>
    <limit effort="3" lower="-0.72" upper="0.72" velocity="70"/>
  </joint>
  <!-- 3. Closed Chain Structure Elements (Auxiliary Linkages) -->
  <!-- Complex 1: Connects to Thigh -->
  <link name="right_linkage_1">
    <visual>
      <origin rpy="0.0 0.0 0.0" xyz="0.0 0.0 0"/>
      <geometry>
        <box size="0.04 0.01 0.17"/>
      </geometry>
      <material name="orange"/>
    </visual>
    <inertial>
      <mass value="0.05"/>
      <inertia ixx="0.00012083333333333335" ixy="0.0" ixz="0.0" iyy="7.083333333333334e-06" iyz="0.0" izz="0.00012708333333333335"/>
    </inertial>
  </link>
  <joint name="right_linkage_1_joint" type="revolute">
    <origin rpy="0.0 1.5707963267948966 0.0" xyz="0.0 0.0 -0.15"/>
    <parent link="right_thigh_link"/>
    <child link="right_linkage_1"/>
    <axis xyz="0.0 1 0.0"/>
    <limit effort="3" lower="-0.72" upper="0.72" velocity="70"/>
  </joint>
  <!-- Complex 2: Connects to Thigh -->
  <link name="right_linkage_2">
    <visual>
      <origin rpy="0.0 0.0 0.0" xyz="0.0 0.0 0.0425"/>
      <geometry>
        <box size="0.04 0.01 0.085"/>
      </geometry>
      <material name="orange"/>
    </visual>
    <inertial>
      <mass value="0.05"/>
      <inertia ixx="3.052083333333334e-05" ixy="0.0" ixz="0.0" iyy="7.083333333333334e-06" iyz="0.0" izz="3.677083333333334e-05"/>
    </inertial>
  </link>
  <joint name="right_linkage_2_joint" type="revolute">
    <origin rpy="0 2.6179938779914944 0" xyz="0 -0.255 0"/>
    <parent link="base_link"/>
    <child link="right_linkage_2"/>
    <axis xyz="0.0 1 0.0"/>
    <limit effort="3" lower="-0.72" upper="0.72" velocity="70"/>
  </joint>
  <!-- Cross Connection 1: Connects to Linkage 2 -->
  <!-- Originally 'first_connect_complex' parent 'second_complex' (linkage_2) -->
  <link name="right_cross_conn_1">
    <visual>
      <origin rpy="0.0 0.0 0.0" xyz="0 0.0 0.07"/>
      <geometry>
        <box size="0.02 0.01 0.17"/>
      </geometry>
      <material name="white"/>
    </visual>
    <inertial>
      <mass value="0.02"/>
      <inertia ixx="4.833333333333335e-05" ixy="0.0" ixz="0.0" iyy="8.333333333333334e-07" iyz="0.0" izz="4.8833333333333346e-05"/>
    </inertial>
  </link>
  <joint name="right_cross_conn_1_joint" type="continuous">
    <origin rpy="0.0 1.5707963267948966 0.0" xyz="0 0 0.07"/>
    <parent link="right_linkage_2"/>
    <child link="right_cross_conn_1"/>
    <axis xyz="0.0 1 0.0"/>
  </joint>
  <!-- Cross Connection 2: Connects to Linkage 1 -->
  <!-- Originally 'second_connect_complex' parent 'first_complex' (linkage_1) -->
  <link name="right_cross_conn_2">
    <visual>
      <origin rpy="0.0 0.0 0.0" xyz="0 0.0 0.07"/>
      <geometry>
        <box size="0.02 0.01 0.17"/>
      </geometry>
      <material name="white"/>
    </visual>
    <inertial>
      <mass value="0.02"/>
      <inertia ixx="4.833333333333335e-05" ixy="0.0" ixz="0.0" iyy="8.333333333333334e-07" iyz="0.0" izz="4.8833333333333346e-05"/>
    </inertial>
  </link>
  <joint name="right_cross_conn_2_joint" type="continuous">
    <origin rpy="0.0 1.5707963267948966 0.0" xyz="0 0 -0.07"/>
    <parent link="right_linkage_1"/>
    <child link="right_cross_conn_2"/>
    <axis xyz="0.0 1 0.0"/>
  </joint>
  <!-- 4. Wheel -->
  <link name="right_wheel_link">
    <visual>
      <origin rpy="1.5707963267948966 0 0" xyz="0 0 0"/>
      <geometry>
        <cylinder length="0.03" radius="0.1"/>
      </geometry>
      <material name="black"/>
    </visual>
    <collision>
      <origin rpy="1.5707963267948966 0 0" xyz="0 0 0"/>
      <geometry>
        <cylinder length="0.03" radius="0.1"/>
      </geometry>
    </collision>
    <inertial>
      <mass value="0.5"/>
      <inertia ixx="0.0012875000000000002" ixy="0.0" ixz="0.0" iyy="0.0012875000000000002" iyz="0.0" izz="0.0025000000000000005"/>
    </inertial>
  </link>
  <joint name="right_wheel_joint" type="continuous">
    <origin rpy="0 0 0" xyz="0 0 -0.5"/>
    <parent link="right_shank_link"/>
    <child link="right_wheel_link"/>
    <axis xyz="0 1 0"/>
    <limit effort="100" velocity="100"/>
  </joint>
  <gazebo reference="right_wheel_link">
    <mu1>1.0</mu1>
    <mu2>1.0</mu2>
    <kp>1000000.0</kp>
    <kd>100.0</kd>
    <material>Gazebo/Black</material>
  </gazebo>
  <!-- Wheel Transmission -->
  <transmission name="right_wheel_trans">
    <type>transmission_interface/SimpleTransmission</type>
    <joint name="right_wheel_joint">
      <hardwareInterface>hardware_interface/EffortJointInterface</hardwareInterface>
    </joint>
    <actuator name="right_wheel_motor">
      <hardwareInterface>hardware_interface/EffortJointInterface</hardwareInterface>
      <mechanicalReduction>1</mechanicalReduction>
    </actuator>
  </transmission>
  <gazebo>
    <joint name="right_cross_conn_1_loop_joint" type="revolute">
      <parent>right_cross_conn_1</parent>
      <child>right_linkage_1</child>
      <axis>
        <xyz>0 1 0</xyz>
        <limit effort="10" lower="-3.14" upper="3.14" velocity="100"/>
      </axis>
      <pose>0 0 -0.07 0 0 0</pose>
    </joint>
  </gazebo>
  <gazebo>
    <joint name="right_cross_conn_2_loop_joint" type="revolute">
      <parent>right_cross_conn_2</parent>
      <child>right_shank_link</child>
      <axis>
        <xyz>0 1 0</xyz>
        <limit effort="10" lower="-3.14" upper="3.14" velocity="100"/>
      </axis>
      <pose>0 0 -0.07 0 0 0</pose>
    </joint>
  </gazebo>
  <!-- =================================================================================== -->
  <!-- Gazebo Plugins -->
  <!-- =================================================================================== -->
  <gazebo>
    <plugin filename="libgazebo_ros_control.so" name="gazebo_ros_control">
      <robotNamespace>/</robotNamespace>
    </plugin>
  </gazebo>
  <gazebo reference="gimbal_imu_link">
    <gravity>true</gravity>
    <sensor name="muzzle_imu_sensor" type="imu">
      <always_on>true</always_on>
      <update_rate>1000</update_rate>
      <visualize>true</visualize>
      <imu/>
      <plugin filename="libgazebo_ros_imu_sensor.so" name="muzzle_imu_plugin">
        <topicName>gimbal_imu</topicName>
        <bodyName>gimbal_imu_link</bodyName>
        <updateRateHZ>100.0</updateRateHZ>
        <gaussianNoise>0.0</gaussianNoise>
        <xyzOffset>0 0 0</xyzOffset>
        <rpyOffset>0 0 0</rpyOffset>
        <frameName>muzzle_link</frameName>
        <initialOrientationAsReference>false</initialOrientationAsReference>
      </plugin>
    </sensor>
  </gazebo>
  <gazebo reference="imu_link">
    <gravity>true</gravity>
    <sensor name="imu_sensor" type="imu">
      <always_on>true</always_on>
      <update_rate>1000</update_rate>
      <visualize>true</visualize>
      <imu/>
      <plugin filename="libgazebo_ros_imu_sensor.so" name="imu_plugin">
        <topicName>imu</topicName>
        <bodyName>imu_link</bodyName>
        <updateRateHZ>100.0</updateRateHZ>
        <gaussianNoise>0.0</gaussianNoise>
        <xyzOffset>0 0 0</xyzOffset>
        <rpyOffset>0 0 0</rpyOffset>
        <frameName>imu_link</frameName>
        <initialOrientationAsReference>false</initialOrientationAsReference>
      </plugin>
    </sensor>
  </gazebo>
</robot>

